Workbook
Name SegmentaciónDeDatos_Plataforma: #N/A
Name SegmentaciónDeDatos_Proveedor: #N/A

Sheet Principal
A1: Klifnet Control
B6: Num | C6: interno | D6: icc | E6: msisdn | F6: imei | G6: Nombre | H6: Imei Corto | I6: imei2 | J6: Equipos | K6: Grupo | L6: Grupos | M6: Plataforma | N6: Proveedor | O6: Vencimiento | P6: Plat Num | Q6: Arrendam | R6: Precio | S6: Periodos
B7: =600+Tabla3[[#This Row],[interno]] -> 616 | C7: 16 | D7: 3331156832 | E7: 8952020920150232311 | F7: 3030690 | G7: Miniban | H7: 3030690 | I7: 3030690 | J7: Cellocator CR300 | K7: LMarquez | L7: Klifnet_mgr | M7: wialon | N7: 04 Telcel | P7: 1
B8: =600+Tabla3[[#This Row],[interno]] -> 635 | C8: 35 | D8: 3781166901 | E8: 8952020220552713491 | F8: 3032746 | G8: KingRanch | H8: 3032746 | I8: 3032746 | J8: Cellocator CR300 | K8: EdificacionBR | L8: Klifnet_mgr | M8: Wialon | N8: 04 Telcel | P8: 1
B9: 71 | C9: 71 | D9: 8934075200001756186 | E9: 345901005893932 | F9: 007288520 | G9: Kenwort 832-AR5 | H9: 007288520 | I9: 356430072885204 | J9: Suntech ST300R | K9: TransportesGomo | L9: Klifnet_mgr | M9: Wialon | N9: 01 Emprenet | P9: 1
B10: 115 | C10: 115 | D10: 8934076200000602976 | E10: 345901007849287 | F10: 007354146 | G10: CHEVROLET CORRALES | H10: 007354146 | I10: 356430073541467 | J10: Suntech ST300R | K10: Zacaula2 | L10: Klifnet_mgr | M10: Wialon | N10: 01 Emprenet | P10: 1
B11: 116 | C11: 116 | D11: 8934076200000602984 | E11: 345901007873411 | F11: 007354147 | G11: C-NP300 (7) Mensajeria ALDAIR | H11: 007354147 | I11: 356430073541475 | J11: Suntech ST300R | K11: Sistelec | L11: Grupo Aconcagua | M11: Wialon | N11: 01 Emprenet | P11: 1
B12: 514 | C12: 314 | D12: 8988303000007662282 | F12: 007354271 | G12: Ford | H12: 007354271 | I12: 356430073542713 | J12: Suntech ST300R | K12: ElMundoPAG | L12: Klifnet_mgr | M12: Wialon | N12: 02 Emnify
B13: 103 | C13: 103 | D13: 8934076200000588274 | E13: 345901007885597 | F13: 007391151 | G13: F-350 | H13: 007391151 | I13: 356430073911512 | J13: Suntech ST300R | K13: Plasticos_VPSA | L13: Klifnet_mgr | M13: Wialon | N13: 01 Emprenet | P13: 1
B14: 98 | C14: 98 | D14: 8934076200000586765 | E14: 345901007840852 | F14: 007391801 | G14: ( ) GDL Ford 2019 F-550 JW16700 J. Luis Bernardino | H14: 007391801 | I14: 356430073918012 | J14: Suntech ST300R | K14: Austin_GDL | L14: Austin Powder | M14: Wialon | N14: 01 Emprenet | P14: 1
B15: 94 | C15: 94 | D15: 8934076200000586716 | E15: 345901007872003 | F15: 007391803 | G15: GDL 16 Ford 3.5 Tons | H15: 007391803 | I15: 356430073918038 | J15: Suntech ST300R | K15: GrupoAconcaguaGDL | L15: Grupo Aconcagua | M15: Wialon | N15: 01 Emprenet | P15: 1
B16: 101 | C16: 101 | D16: 8934076200000587052 | E16: 345901007841498 | F16: 007391816 | G16: ( ) GDL Ford F-350 JW17183 David D | H16: 007391816 | I16: 356430073918160 | J16: Suntech ST300R | K16: Austin_Explosivos | L16: Austin Powder | M16: Wialon | N16: 01 Emprenet | P16: 1
B17: 102 | C17: 102 | D17: 8934076200000587060 | E17: 345901007887289 | F17: 007391817 | G17: ( ) GDL Ford F350 JW17184 David D | H17: 007391817 | I17: 356430073918178 | J17: Suntech ST300R | K17: Austin_Explosivos | L17: Austin Powder | M17: Wialon | N17: 01 Emprenet | P17: 1
B18: 100 | C18: 100 | D18: 8934076200000587011 | E18: 345901007887420 | F18: 007442030 | G18: CAMIONETA VW ROBUST | H18: 007442030 | I18: 356430074420307 | J18: Suntech ST300R | K18: Logyca | L18: Klifnet_mgr | M18: Wialon | N18: 01 Emprenet | P18: 1
B19: 54 | C19: 54 | D19: 8934072400005801904 | E19: 345901007627849 | F19: 008441190 | G19: ( ) GDL NP300 2021 JX03401 Jorge Garcia | H19: 008441190 | I19: 352580084411904 | J19: Suntech ST600R | K19: Sidney_Explosivos | L19: Austin Powder | M19: Wialon | N19: 01 Emprenet | P19: 1
B20: 69 | C20: 69 | D20: 8934075200001755840 | E20: 345901005875288 | F20: 008441204 | G20: GDL 14 International | H20: 008441204 | I20: 352580084412043 | J20: Suntech ST600R | K20: GrupoAconcaguaGDL | L20: Grupo Aconcagua | M20: Wialon | N20: 01 Emprenet | P20: 1
B21: 52 | C21: 52 | D21: 8934072400005801870 | E21: 345901007685628 | F21: 008508003 | G21: TRACTO FREIGHTLINE | H21: 008508003 | I21: 352580085080039 | J21: Suntech ST600R | K21: Logyca | L21: Klifnet_mgr | M21: Wialon | N21: 01 Emprenet | P21: 1
B22: 61 | C22: 61 | D22: 8934075200001755659 | E22: 345901005874740 | F22: 008595223 | G22: Jamoneta | H22: 008595223 | I22: 352580085952237 | J22: Suntech ST600R | K22: SandraDennisse | L22: Klifnet_mgr | M22: Wialon | N22: 01 Emprenet | P22: 1
B23: 567 | C23: 128 | D23: 8934077200000974127 | E23: 345901005488216 | F23: 008598594 | G23: Ram 4500 | H23: 008598594 | I23: 352580085985948 | J23: Suntech ST600R | K23: UniversalAzulejos | L23: Klifnet_mgr | M23: Wialon | N23: 15 Baja Emprenet | P23: 1
B24: =600+Tabla3[[#This Row],[interno]] -> 610 | C24: 10 | D24: 3331156603 | E24: 3331156603 | F24: 010052530 | G24: Nissan M1 | H24: 010052530 | J24: Suntech ST600R | K24: GrupoAconcaguaNorte | L24: Grupo Aconcagua | M24: Wialon | N24: 04 Telcel | P24: 1
B25: =600+Tabla3[[#This Row],[interno]] -> 622 | C25: 22 | D25: 3339561780 | E25: 3339561780 | F25: 010057207 | G25: MTY CG-04 | H25: 010057207 | J25: Suntech ST600R | K25: GrupoAconcaguaNorte | L25: Grupo Aconcagua | M25: Wialon | N25: 04 Telcel | P25: 1
B26: =600+Tabla3[[#This Row],[interno]] -> 607 | C26: 7 | D26: 3316026798 | E26: 3316026798 | F26: 010057798 | G26: MTY CG-13 | H26: 010057798 | J26: Suntech ST600R | K26: GrupoAconcaguaNorte | L26: Grupo Aconcagua | M26: Wialon | N26: 04 Telcel | P26: 1
B27: 434 | C27: 234 | D27: 8988303000007662185 | E27: Emnify | F27: 010070280 | G27: GDL 10 International/cambio sim emnify | H27: 010070280 | J27: Suntech ST600R | K27: GrupoAconcaguaGDL | L27: Grupo Aconcagua | M27: Wialon | N27: 02 Emnify
B28: 291 | C28: 91 | D28: 8988303000006249362 | E28: Emnify | F28: 010169932 | G28: Isuzu PF-41-279 | H28: 010169932 | J28: Suntech ST600R | K28: GQGLOBAL | L28: Klifnet_mgr | M28: Wialon | N28: 02 Emnify
B29: 292 | C29: 92 | D29: 8988303000006249363 | E29: Emnify | F29: 010170100 | G29: Isuzu PF-41-278 | H29: 010170100 | J29: Suntech ST600R | K29: GQGLOBAL | L29: Klifnet_mgr | M29: Wialon | N29: 02 Emnify
B30: 294 | C30: 94 | D30: 8988303000006249365 | E30: Emnify | F30: 010178193 | G30: camion 4 | H30: 010178193 | J30: Suntech ST600R | K30: GQGLOBAL | L30: Klifnet_mgr | M30: Wialon | N30: 02 Emnify
B31: 293 | C31: 93 | D31: 8988303000006249364 | E31: Emnify | F31: 010178850 | G31: Isuzu PF-32-761 Eco 03 | H31: 010178850 | J31: Suntech ST600R | K31: GQGLOBAL | L31: Klifnet_mgr | M31: Wialon | N31: 02 Emnify
B32: 304 | C32: 104 | D32: 8988303000006249375 | E32: Emnify | F32: 010179000 | G32: Cascadia 02 | H32: 010179000 | I32: 353380101790003 | J32: Suntech ST600R | K32: TransportesMS | L32: Klifnet_mgr | M32: Wialon | N32: 02 Emnify | O32: baja Suspensión
B33: 27 | C33: 27 | D33: 8934072100260760502 | E33: 345901005027993 | F33: 205222098 | G33: SO-N77 | H33: 205222098 | I33: 358222052220983 | J33: Suntech ST300R | K33: TransportesSolorio | L33: Klifnet_mgr | M33: Wialon | N33: 01 Emprenet | P33: 1
B34: 4 | C34: 4 | D34: 8934071100292767278 | E34: 345901000869321 | F34: 205452049 | G34: M-04 | H34: 205452049 | I34: 358222054520497 | J34: Suntech ST300R | K34: MutualidadMinerva | L34: Klifnet_mgr | M34: Wialon | N34: 01 Emprenet | P34: 1
B35: 13 | C35: 13 | D35: 8934072100260760205 | E35: 345901000198463 | F35: 205475417 | G35: Ranger MSV-0608 | H35: 205475417 | I35: 358222054754179 | J35: Suntech ST300R | K35: Vika | L35: Klifnet_mgr | M35: Wialon | N35: 01 Emprenet | P35: 1
B36: 12 | C36: 12 | D36: 8934072100260760197 | E36: 345901005013578 | F36: 205475420 | G36: Nissan NP300 | H36: 205475420 | I36: 358222054754203 | J36: Suntech ST300R | K36: Vika | L36: Klifnet_mgr | M36: Wialon | N36: 01 Emprenet | P36: 1
B37: 16 | C37: 16 | D37: 8934072100260760304 | E37: 345901000245790 | F37: 205475493 | G37: ( ) GDL Ranger FB85711 - Antonio Rios | H37: 205475493 | I37: 358222054754930 | J37: Suntech ST300R | K37: Sidney_GDL | L37: Austin Powder | M37: Wialon | N37: 01 Emprenet | P37: 1
B38: 17 | C38: 17 | D38: 8934072100260760312 | E38: 345901000297968 | F38: 205475494 | G38: #04 International JU-51 132 | H38: 205475494 | I38: 358222054754948 | J38: Suntech ST300R | K38: Grupo AconcaguaMX | L38: Grupo Aconcagua | M38: Wialon | N38: 01 Emprenet | P38: 1
B39: 15 | C39: 15 | D39: 8934072100260760247 | E39: 345901000207797 | F39: 205475495 | G39: ( ) GDL L200 FB86301 - JULIO GOMEZ | H39: 205475495 | I39: 358222054754955 | J39: Suntech ST300R | K39: Sidney_GDL | L39: Austin Powder | M39: Wialon | N39: 01 Emprenet | P39: 1
B40: 22 | C40: 22 | D40: 8934072100260760395 | E40: 345901005016752 | F40: 205475497 | G40: GDL 01 International | H40: 205475497 | I40: 358222054754971 | J40: Suntech ST300R | K40: GrupoAconcaguaGDL | L40: Grupo Aconcagua | M40: Wialon | N40: 01 Emprenet | P40: 1
B41: 23 | C41: 23 | D41: 8934072100260760403 | E41: 345901000679862 | F41: 205475499 | G41: GDL 11 Dina | H41: 205475499 | I41: 358222054754997 | J41: Suntech ST300R | K41: GrupoAconcaguaGDL | L41: Grupo Aconcagua | M41: Wialon | N41: 01 Emprenet | P41: 1
B42: 18 | C42: 18 | D42: 8934072100260760320 | E42: 345901000243486 | F42: 205475504 | G42: ( ) GDL Jeep Patriot-ALVARO MINAKATA | H42: 205475504 | I42: 358222054755044 | J42: Suntech ST300R | K42: Sidney_GDL | L42: Austin Powder | M42: Wialon | N42: 01 Emprenet | P42: 1
B43: 21 | C43: 21 | D43: 8934072100260760387 | E43: 345901005049007 | F43: 205475505 | G43: ( ) GDL NP300 EXPLOSIVOS - David D. | H43: 205475505 | I43: 358222054755051 | J43: Suntech ST300R | K43: Austin_Explosivos | L43: Austin Powder | M43: Wialon | N43: 01 Emprenet | P43: 1
B44: 19 | C44: 19 | D44: 8934072100260760338 | E44: 345901005017951 | F44: 205475506 | G44: ( ) GDL Hilux GRIS SWF - CHOFERES | H44: 205475506 | I44: 358222054755069 | J44: Suntech ST300R | K44: Austin_GDL | L44: Austin Powder | M44: Wialon | N44: 01 Emprenet | P44: 1
...

Sheet StockEmprenet
B1: 8934071200001278284 | C1: 345901012473523 | G1: 356614028649299 | K1: Stock | L1: Emprenet
B2: 8934071200001278383 | C2: 345901012473524 | K2: Stock | L2: Emprenet
B3: 8934071200001278367 | C3: 345901012473537 | K3: Stock | L3: Emprenet
B4: 8934071200001278359 | C4: 345901012477405 | K4: Stock | L4: Emprenet
B5: 8934071200001277989 | C5: 345901012477406 | K5: Stock | L5: Emprenet
B6: 8934071200001278391 | C6: 345901012472066 | K6: Stock | L6: Emprenet
B7: 8934071200001278375 | C7: 345901012472064 | K7: Stock | L7: Emprenet
B8: 8934071200001278268 | C8: 345901012475675 | K8: Stock | L8: Emprenet
B9: 8934071200001278276 | C9: 345901012473592 | K9: Stock | L9: Emprenet
B10: 8934071200001278334 | C10: 345901012473631 | K10: Stock | L10: Emprenet
B11: 8934071200001278243 | C11: 345901012473633 | K11: Stock | L11: Emprenet
B12: 8934071200001277997 | C12: 345901012477465 | K12: Stock | L12: Emprenet
B13: 8934071200001278292 | C13: 345901012473933 | K13: Stock | L13: Emprenet
... B20: 8934071200001278318 | C20: 345901012471005 | K20: Stock | L20: Emprenet

Sheet Costos
B3: Proveedor | C3: Costo | D3: Cantidad | E3: Costo Unitario
B4: Emprenet | C4: 8000 | D4: =COUNTIF(Principal!M:M,Costos!B4) -> 0 | E4: =C4/D4 -> #DIV/0!
B5: GlobalSat | C5: 0 | D5: =COUNTIF(Principal!M:M,Costos!B5) -> 0 | E5: =C5/D5 -> #DIV/0!
B6: Telcel | C6: 2100 | D6: =COUNTIF(Principal!M:M,Costos!B6) -> 0 | E6: =C6/D6 -> #DIV/0!
B7: TelcelPrep | C7: 200 | D7: =COUNTIF(Principal!M:M,Costos!B7) -> 0 | E7: =C7/D7 -> #DIV/0!
B8: WeMobile | C8: 1800 | D8: =COUNTIF(Principal!M:M,Costos!B8) -> 0 | E8: =C8/D8 -> #DIV/0!
B9: Zemnify | C9: =80*J9 -> 1692.44 | D9: =COUNTIF(Principal!M:M,Costos!B9) -> 0 | E9: =C9/D9 -> #DIV/0! | I9: #VALUE! | J9: {=_FV(I9,"Cierre anterior",TRUE)} -> 21.1555
B10: Wialon | C10: =940*J10 -> 16882.4 | D10: =COUNTIF(Principal!L:L,Costos!B10) -> 0 | E10: =C10/D10 -> #DIV/0! | I10: #VALUE! | J10: {=_FV(I10,"Cierre anterior",TRUE)} -> 17.96
B11: Imovit | C11: 320 | D11: =COUNTIF(Principal!L:L,Costos!B11) -> 3 | E11: =C11/D11 -> 106.66667

Sheet Reporte
A1: Fecha | B1: Proveedor | C1: Cantidad | D1: Costo Unitario
A2: 44347 | B2: Imovit | C2: 8 | D2: 40
A3: 44347 | B3: Wialon | C3: 329 | D3: 56.988857
A4: 44347 | B4: Zemnify | C4: 53 | D4: 36.806189
A5: 44347 | B5: WeMobile | C5: 43 | D5: 41.860465
A6: 44347 | B6: TelcelPrep | C6: 10 | D6: 20
A7: 44347 | B7: Telcel | C7: 40 | D7: 52.5
A8: 44347 | B8: GlobalSat | C8: 1 | D8: 0
A9: 44347 | B9: Emprenet | C9: 220 | D9: 36.363636

Sheet Hoja5

Sheet Baja28042021
A1: Num | B1: icc | C1: msisdn | D1: imei | E1: Nombre | F1: Imei Corto | G1: imei | H1: Equipos | I1: Grupo | J1: Grupos | K1: Plataforma | M1: Plat Num
A2: 24 | B2: 8934072100260760361 | C2: 345901000193266 | D2: 205475498 | E2: L200-Basilio Hernandez | F2: 205475498 | G2: 205475498 | H2: Suntech ST300R | I2: baja | J2: Austin Powder | K2: Cancelar | L2: Emprenet | M2: 1
A3: 38 | B3: 8934072100260950665 | C3: 345901005018036 | D3: 205913838 | E3: C3-Grua Intern 2012 (3) JESUS | F3: 205913838 | G3: 205913838 | H3: Suntech ST300R | I3: baja | J3: Grupo Aconcagua | K3: Cancelar | L3: Emprenet | M3: 1
A4: 39 | B4: 8934072100260950657 | C4: 345901000216195 | D4: 205913837 | E4: C-Grua - Mercedes - Patio (4) Oscar | G4: 205913837 | H4: Suntech ST300R | I4: baja | J4: Grupo Aconcagua | K4: Cancelar | L4: Emprenet | M4: 1
A5: 40 | B5: 8934072100260950681 | C5: 345901005051131 | D5: 205913846 | E5: C-Grua 2004 (2) Salvador | F5: 205913846 | G5: 205913846 | H5: Suntech ST300R | I5: baja | J5: Grupo Aconcagua | K5: Cancelar | L5: Emprenet | M5: 1
A7: 255 | B7: 3781165092 | C7: 3781165092 | D7: 010068819 | E7: RAM 4000 Edgar | F7: 010068819 | H7: ST600R | I7: baja | J7: Cancelar | K7: Cancelar | L7: Telcel | M7: 1
A8: 286 | B8: 3339561883 | C8: 3339561883 | D8: 0520000260 | E8: (49) Ram 350 FB-86332 | F8: 868446031790690 | H8: Suntech ST600-UP | I8: baja | J8: Cancelar | K8: Cancelar | L8: Telcel | M8: 1

Sheet Hoja2
A1: Emprenet | F1: Wialon
A2: #04 International JU-51 132 | B2: 205475494 | C2: 205475494 | D2: Suntech ST300R | E2: GrupoAconcaguaMX | F2: #04 International JU-51 132 | G2: GrupoAconcaguaMX | H2: Grupo AconcaguaMX | I2: Suntech ST300R | J2: 205475494
A3: (53) Ram Gris FB-86338 Abraham Hdz | B3: 864802030384006 | C3: 864802030384006 | D3: Queclink GV75 | E3: ImplementosDgo | F3: (53) Ram Gris FB-86338 Abraham Hdz | G3: ImplementosDgo | H3: ImplementosDgo | I3: Queclink GV75 | J3: 864802030384006
F4: (55) Ram FB-86329 | G4: ImplementosDgo | H4: ImplementosDgo | I4: Skypatrol TT8750 | J4: 011722002277552
A5: (57) Kenworth FB-86327 ZAC (JOSE ALFONSO) | B5: 864802030312908 | C5: 864802030312908 | D5: Queclink GV75 | E5: ImplementosDgo | F5: (57) Kenworth FB-86327 ZAC (JOSE ALFONSO) | G5: ImplementosDgo | H5: ImplementosDgo | I5: Queclink GV75 | J5: 864802030312908
A6: (62) Colorado FB-86317 | B6: 205929247 | C6: 205929247 | D6: Suntech ST300R | E6: ImplementosDgo | F6: (62) Colorado FB-86317 | G6: ImplementosDgo | H6: ImplementosDgo | I6: Suntech ST300R | J6: 205929247
A7: (65) Ranger FB-86318 Hazael | B7: 863286020813847 | C7: 863286020813847 | D7: Queclink GV300 | E7: ImplementosDgo | F7: (65) Ranger FB-86318 Hazael | G7: ImplementosDgo | H7: ImplementosDgo | I7: Queclink GV300 | J7: 863286020813847
A8: (78) Hilux FB-86336 Roberto S | B8: 864802030318186 | C8: 864802030318186 | D8: Queclink GV75 | E8: ImplementosDgo | F8: (78) Hilux FB-86336 Roberto S | G8: ImplementosDgo | H8: ImplementosDgo | I8: Queclink GV75 | J8: 864802030318186
A9: (80) Kenworth FB-86339 (JESUS BUEN ROSTRO) | B9: 868789022565666 | C9: 868789022565666 | D9: Queclink GV300 | E9: ImplementosDgo | F9: (80) Kenworth FB-86339 (JESUS BUEN ROSTRO) | G9: ImplementosDgo | H9: ImplementosDgo | I9: Queclink GV300 | J9: 868789022565666
A10: (87) Ranger FB-86344 Daniel Razo | B10: 864802030331445 | C10: 864802030331445 | D10: Queclink GV75 | E10: ImplementosDgo | F10: (87) Ranger FB-86344 Daniel Razo | G10: ImplementosDgo | H10: ImplementosDgo | I10: Queclink GV75 | J10: 864802030331445
A11: (88) Silverado FM9848-A Victor | B11: 864802030314599 | C11: 864802030314599 | D11: Queclink GV75 | E11: ImplementosDgo | F11: (88) Silverado FM9848-A Victor | G11: ImplementosDgo | H11: ImplementosDgo | I11: Queclink GV75 | J11: 864802030314599
F12: 06 NISSAN GM 51 233 | G12: E_Migliore | H12: E_Migliore | I12: Cellocator CR200 | J12: 1095691
A13: 1 Isuzu GG 41 054 A | B13: 868789026072743 | C13: 868789026072743 | D13: Queclink GV300 | E13: E_Migliore | F13: 1 Isuzu GG 41 054 A | G13: E_Migliore | H13: E_Migliore | I13: Queclink GV300 | J13: 868789026072743
A14: 2 Isuzu GR-36332 | B14: 868789021389787 | C14: 868789021389787 | D14: Queclink GV300 | E14: E_Migliore | F14: 2 Isuzu GR-36332 | G14: E_Migliore | H14: E_Migliore | I14: Queclink GV300 | J14: 868789021389787
A15: 3 Isuzu GP 239 70 | B15: 868789021396733 | C15: 868789021396733 | D15: Queclink GV300 | E15: E_Migliore | F15: 3 Isuzu GP 239 70 | G15: E_Migliore | H15: E_Migliore | I15: Queclink GV300 | J15: 868789021396733
A16: 4 Isuzu GN-29478 | B16: 868789021389886 | C16: 868789021389886 | D16: Queclink GV300 | E16: E_Migliore | F16: 4 Isuzu GN-29478 | G16: E_Migliore | H16: E_Migliore | I16: Queclink GV300 | J16: 868789021389886
A17: A HIACE JNH-85-67 | B17: 205463388 | C17: 205463388 | D17: Suntech ST300R | E17: AutorentGDL | F17: A HIACE JNH-85-67 | G17: AutorentGDL | H17: AutorentGDL | I17: Suntech ST300R | J17: 205463388
A18: A TOWN & COUNTRY JMZ-61-80 | B18: 205496941 | C18: 205496941 | D18: Suntech ST300R | E18: AutorentGDL | F18: A TOWN & COUNTRY JMZ-61-80 | G18: AutorentGDL | H18: AutorentGDL | I18: Suntech ST300R | J18: 205496941
A19: A VENTO NEGRO JNG-7919 | B19: 862193027825223 | C19: 862193027825223 | D19: Queclink GV55 | E19: AutorentGDL | F19: A VENTO NEGRO JNG-7919 | G19: AutorentGDL | H19: AutorentGDL | I19: Queclink GV55 | J19: 862193027825223
A20: Aveo Morelia | B20: 863830031811546 | C20: 863830031811546 | D20: Queclink GV55 | E20: IDAsesoria | F20: Aveo Morelia | G20: IDAsesoria | H20: IDAsesoria | I20: Queclink GV55 | J20: 863830031811546
A21: AVEO OFICINA - Erik Gonzalez | B21: 863830030158568 | C21: 863830030158568 | D21: Queclink GV55 | E21: Sidney_GDL | F21: AVEO OFICINA - Erik Gonzalez | G21: Sidney_GDL | H21: Sidney_GDL | I21: Queclink GV55 | J21: 863830030158568
A22: AVEO UKD-750-N | B22: 205462898 | C22: 205462898 | D22: Suntech ST300R | E22: AutorentGDL | F22: AVEO UKD-750-N | G22: AutorentGDL | H22: AutorentGDL | I22: Suntech ST300R | J22: 205462898
A23: B HIACE JNX-93-37 | B23: 862193028800316 | C23: 862193028800316 | D23: Queclink GV55 | E23: AutorentGDL | F23: B HIACE JNX-93-37 | G23: AutorentGDL | H23: AutorentGDL | I23: Queclink GV55 | J23: 862193028800316
A24: B TOWN & COUNTRY JNK-6142 | B24: 205475418 | C24: 205475418 | D24: Suntech ST300R | E24: AutorentGDL | F24: B TOWN & COUNTRY JNK-6142 | G24: AutorentGDL | H24: AutorentGDL | I24: Suntech ST300R | J24: 205475418
... A41: CHEVROLET CORRALES | B41: 007354146 | C41: 007354146 | D41: Suntech ST300R | E41: Zacaula2 | F41: CHEVROLET CORRALES | G41: Zacaula2 | H41: Zacaula2 | I41: Suntech ST300R | J41: 007354146
F42: Chevrolet Migliore | G42: E_Migliore | H42: E_Migliore | I42: Suntech ST215 I/E | J42: 844592
A43: Cheyenne | B43: 205913844 | C43: 205913844 | D43: Suntech ST300R | E43: DenisseCasas | F43: Cheyenne | G43: DenisseCasas | H43: DenisseCasas | I43: Suntech ST300R | J43: 205913844
A44: CITY JNG-92-81 | B44: 205462893 | C44: 205462893 | D44: Suntech ST300R | E44: AutorentGDL | F44: CITY JNG-92-81 | G44: AutorentGDL | H44: AutorentGDL | I44: Suntech ST300R | J44: 205462893
A45: C-NP300 2015 (6) Benajmin | B45: 205913839 | C45: 205913839 | D45: Suntech ST300R | E45: Sistelec | F45: C-NP300 2015 (6) Benajmin | G45: Sistelec | H45: Sistelec | I45: Suntech ST300R | J45: 205913839
A46: C-NP300 2018 (8) Rene | B46: 863830030007294 | C46: 863830030007294 | D46: Queclink GV55 | E46: Sistelec | F46: C-NP300 2018 (8) Rene | G46: Sistelec | H46: Sistelec | I46: Queclink GV55 | J46: 863830030007294
A47: C-NP300 Mensajeria Aldair (7) | B47: 007354147 | C47: 007354147 | D47: Suntech ST300R | E47: Sistelec | F47: C-NP300 Mensajeria Aldair (7) | G47: Sistelec | H47: Sistelec | I47: Suntech ST300R | J47: 007354147
A48: C-Ram Rene (5) | B48: 205913335 | C48: 205913335 | D48: Suntech ST300R | E48: Sistelec | F48: C-Ram Rene (5) | G48: Sistelec | H48: Sistelec | I48: Suntech ST300R | J48: 205913335
A49: D VENTO UPH-744-A | B49: 205475422 | C49: 205475422 | D49: Suntech ST300R | E49: AutorentGDL | F49: D VENTO UPH-744-A | G49: AutorentGDL | H49: AutorentGDL | I49: Suntech ST300R | J49: 205475422
F50: Dina 1994 | G50: DavidVarela | H50: DavidVarela | I50: Cellocator CR200 | J50: 1091217
F51: Equipo 093 | G51: Sidney_Explosivos | H51: Sidney_Explosivos | I51: Suntech ST4300 | J51: 0470000093
F52: Equipo 094 | G52: Sidney_Explosivos | H52: Sidney_Explosivos | I52: Suntech ST4300 | J52: 0470000094
F53: Equipos 196 | G53: Sidney_Explosivos | H53: Sidney_Explosivos | I53: Suntech ST4300 | J53: 0470000196
A54: F350 LB-53-879 | B54: 008596481 | C54: 008596481 | D54: Suntech ST600R | E54: GrupoCarmich | F54: F350 LB-53-879 | G54: GrupoCarmich | H54: GrupoCarmich | I54: Suntech ST600R | J54: 008596481
A55: F350-2005 | B55: 868789022709603 | C55: 868789022709603 | D55: Queclink GV300 | E55: Plasticos_VPSA | F55: F350-2005 | G55: Plasticos_VPSA | H55: Plasticos_VPSA | I55: Queclink GV300 | J55: 868789022709603
A56: F350-2018 | B56: 007391151 | C56: 007391151 | D56: Suntech ST300R | E56: Plasticos_VPSA | F56: F350-2018 | G56: Plasticos_VPSA | H56: Plasticos_VPSA | I56: Suntech ST300R | J56: 007391151
...

Sheet Hoja3
A2: Num | B2: Serie GPS | C2: Unidad
A3: 1 | B3: 867688033153531 | C3: A-10 INTERNACIONAL
A4: 2 | B4: 867688036747636 | C4: A-14 International JR-95-591
A5: 3 | B5: 867688036625501 | C5: A-17 HYUNDAI JW44682
A6: 4 | B6: 867688036639387 | C6: A-19 HYUNDAI JW44680
A7: 5 | B7: 867688036640583 | C7: A-21 Hyundai JW-44-681
A8: 6 | B8: 863003042043653 | C8: A-22 International
A9: 7 | B9: 867688036641292 | C9: A-23 Hyundai JW-44-766
A10: 8 | B10: 867688036616989 | C10: A-25 Hyundai JW-44-683
A11: 9 | B11: 863003042119503 | C11: A-27 Izusu JU-87-908
A12: 10 | B12: 867688036627275 | C12: A-30 Kenworth
A13: 11 | B13: 867688033163472 | C13: A-32 Ford
A14: 12 | B14: 863003042123430 | C14: A-33 Sterling
A15: 13 | B15: 863003042077420 | C15: A-34 Mercedes Benz JS-40-621
C20: 8934071200000906919
B21: 3320313792 | C21: 8934075200004640106
B22: 3328200966 | C22: 8934075200004640114
B23: 3329211707 | C23: 8934075200004640122 | D23: pend
B24: 3329211871 | C24: 8934075200004640130 | D24: pend
B25: 3329211890 | C25: 8934075200004640148
B26: 3329211898 | C26: 8934075200004640155
B27: 3329211944 | C27: 8934075200004640163
B28: 3329212042 | C28: 8934075200004640171
B29: 3329212052 | C29: 8934075200004700876
B30: 3329216026 | C30: 8934075200004700884
B31: 3315761332
B32: 3334840708
B33: 3329465176
B34: 3338225936
B35: 3313255752
D39: 0680015866 | E39: 868199054724449 | G39: 39.75 | H39: 27.45
D40: 0680015867 | E40: 868199054609731 | G40: =G39/53 -> 0.75 | H40: =H39/53 -> 0.51792453
D41: 0680015868 | E41: 868199054607859 | G41: =25*G40 -> 18.75 | H41: =25*H40 -> 12.948113 | I41: =G41+H41 -> 31.698113
D42: 0680015869 | E42: 868199054586178
D43: 0680015870 | E43: 868199054622783
D44: 0680015871 | E44: 868199054606091
D45: 0680015872 | E45: 868199054651642
D46: 0680015873 | E46: 868199054609335
D47: 0680015874 | E47: 868199054608261
D48: 0680015875 | E48: 868199054609798
...

Sheet Sugerencia1
A2: Etiquetas de fila | B2: Cuenta de Nombre
A3: Cancelar | B3: 7
A4: Corporativo | B4: 3
A5: Disponible
A6: IMovit | B6: 8
A7: TrackSolid | B7: 25
A8: Ventas IOT | B8: 18
A9: Wialon | B9: 417
A10: (en blanco) | B10: 1
A11: Total general | B11: 479

Sheet Sugerencia2
A2: Etiquetas de fila | B2: Cuenta de Nombre
A3: 01 Emprenet | B3: 176
A4: 02 Emnify | B4: 188
A5: 03 GlobalSat | B5: 1
A6: 04 Telcel | B6: 35
A7: 05 WeMobile | B7: 36
A8: 06 M2MExpress | B8: 1
A9: 07 TelcelPrep | B9: 15
A10: 08 BajaWemobile | B10: 7
A11: 09 Telcel Bajas | B11: 1
A12: 10 Propios | B12: 19
A13: Total general | B13: 479

Sheet Sugerencia3
A2: Etiquetas de fila | B2: Cuenta de Nombre
A3: Cellocator CR200 | B3: 1
A4: Cellocator CR300 | B4: 2
A5: Concox AT4 | B5: 3
A6: Concox AT6 | B6: 13
A7: Concox GT06E | B7: 4
A8: Concox GT06N | B8: 11
A9: Concox Q2 | B9: 1
A10: Concox R83 | B10: 4
A11: Concox WeTrack lite (GV25) | B11: 1
A12: Concox Wetrack2 | B12: 1
A13: ConcoxGT06E | B13: 6
A14: Globalstar SmartOne | B14: 1
... A46: Total general | B46: 479

Sheet Hoja1

Sheet Sugerencia4
A2: Etiquetas de fila | B2: Cuenta de Nombre
A3: ADRIAN JESUS MUNOZ | B3: 2
A4: AgricolaCharay | B4: 1
A5: AGSonorg | B5: 18
A6: AUPANohme | B6: 6
A7: Austin_Explosivos | B7: 7
A8: Austin_GDL | B8: 6
A9: AustinTorreon | B9: 31
A10: AyuntamientoHillo | B10: 1
A11: baja | B11: 8
A12: Bernardo | B12: 18
A13: CenMex | B13: 1
A14: CiriloOrtega | B14: 3
... A84: Zacaula2 | B84: 1
A85: (en blanco)
A86: Total general | B86: 479
